Workbook

Sheet Hoja1
A3: Cuenta de COMPRA
A4: Género | B4: 2024 | C4: 2025 | D4: Total general
A5: Masculino | B5: 859 | C5: 511 | D5: 1370
A6: Femenino | B6: 2243 | C6: 1387 | D6: 3630
A7: Total general | B7: 3102 | C7: 1898 | D7: 5000
A19: Tipo de pago | B19: Promedio de TOTAL A PAGAR
A20: Efectivo | B20: 94.120794
A21: Tarjeta de crédito | B21: 82.938656
A22: Tarjeta Deprati | B22: 94.799386
A23: Total general | B23: 90.222958
A36: Clientes | B36: Edades.
A37: Adultos jóvenes 18 - 35 años | B37: 1856
A38: Adultos mayores 36 años en adelante | B38: 3144
A39: Total general | B39: 5000

Sheet Tienda
A1: ID CLIENTE | B1: GENERO | C1: EDAD | D1: CATEGORIA_EDAD | E1: COMPRA | F1: COLOR | G1: MARCA | H1: CODIGO DE ROPA | I1: FECHA DE COMPRA | J1: AÑO DE COMPRA | K1: PRECIO | L1: DESCUENTO | M1: TOTAL A PAGAR | N1: TIPO DE PAGO | O1: DIFERIDO | P1: FECHA DE CORTE | Q1: MESES DIFERIDO
A2: DEP-A0-0023 | B2: Femenino | C2: 28 | D2: =IF(Tabla1[[#This Row],[EDAD]]<=35,"Adultos jóvenes 18 - 35 años",IF(C2>=36,"Adultos mayores 36 años en adelante")) -> Adultos jóvenes 18 - 35 años | E2: Pantalón | F2: Gris | G2: Adidas | H2: MER-A0-0023 | I2: 45312 | J2: =YEAR(Tabla1[[#This Row],[FECHA DE COMPRA]]) -> 2024 | K2: 11.39 | L2: 0.3 | M2: =Tienda!$K3-Tienda!$K3*Tienda!$L3 -> 21.368 | N2: Efectivo | O2: No | P2: 45312 | Q2: 0
A3: DEP-A0-1736 | B3: Femenino | C3: 24 | D3: =IF(Tabla1[[#This Row],[EDAD]]<=35,"Adultos jóvenes 18 - 35 años",IF(C3>=36,"Adultos mayores 36 años en adelante")) -> Adultos jóvenes 18 - 35 años | E3: Blusa | F3: Verde | G3: Zara | H3: MER-A0-1736 | I3: 45312 | J3: =YEAR(Tabla1[[#This Row],[FECHA DE COMPRA]]) -> 2024 | K3: 26.71 | L3: 0.2 | M3: =Tienda!$K4-Tienda!$K4*Tienda!$L4 -> 49.994 | N3: Efectivo | O3: No | P3: 45312 | Q3: 0
A4: DEP-A0-3526 | B4: Masculino | C4: 31 | D4: =IF(Tabla1[[#This Row],[EDAD]]<=35,"Adultos jóvenes 18 - 35 años",IF(C4>=36,"Adultos mayores 36 años en adelante")) -> Adultos jóvenes 18 - 35 años | E4: Camisa | F4: Blanco | G4: Mango | H4: MER-A0-3526 | I4: 45313 | J4: =YEAR(Tabla1[[#This Row],[FECHA DE COMPRA]]) -> 2024 | K4: 71.42 | L4: 0.3 | M4: =Tienda!$K5-Tienda!$K5*Tienda!$L5 -> 48.111 | N4: Efectivo | O4: No | P4: 45313 | Q4: 0
A5: DEP-A0-4042 | B5: Femenino | C5: 30 | D5: =IF(Tabla1[[#This Row],[EDAD]]<=35,"Adultos jóvenes 18 - 35 años",IF(C5>=36,"Adultos mayores 36 años en adelante")) -> Adultos jóvenes 18 - 35 años | E5: Falda | F5: Blanco | G5: Mango | H5: MER-A0-4042 | I5: 45314 | J5: =YEAR(Tabla1[[#This Row],[FECHA DE COMPRA]]) -> 2024 | K5: 68.73 | L5: 0.3 | M5: =Tienda!$K7-Tienda!$K7*Tienda!$L7 -> 18.16 | N5: Efectivo | O5: No | P5: 45314 | Q5: 0
A6: DEP-A0-0519 | B6: Femenino | C6: 22 | D6: =IF(Tabla1[[#This Row],[EDAD]]<=35,"Adultos jóvenes 18 - 35 años",IF(C6>=36,"Adultos mayores 36 años en adelante")) -> Adultos jóvenes 18 - 35 años | E6: Blusa | F6: Verde | G6: Nike | H6: MER-A0-0519 | I6: 45318 | J6: =YEAR(Tabla1[[#This Row],[FECHA DE COMPRA]]) -> 2024 | K6: 10.65 | L6: 0 | M6: =Tienda!$K12-Tienda!$K12*Tienda!$L12 -> 19.75 | N6: Efectivo | O6: No | P6: 45318 | Q6: 0
A7: DEP-A0-4183 | B7: Masculino | C7: 29 | D7: =IF(Tabla1[[#This Row],[EDAD]]<=35,"Adultos jóvenes 18 - 35 años",IF(C7>=36,"Adultos mayores 36 años en adelante")) -> Adultos jóvenes 18 - 35 años | E7: Chaqueta | F7: Negro | G7: Mango | H7: MER-A0-4183 | I7: 45319 | J7: =YEAR(Tabla1[[#This Row],[FECHA DE COMPRA]]) -> 2024 | K7: 22.7 | L7: 0.2 | M7: =Tienda!$K16-Tienda!$K16*Tienda!$L16 -> 128.023 | N7: Efectivo | O7: No | P7: 45319 | Q7: 0
A8: DEP-A0-4126 | B8: Femenino | C8: 22 | D8: =IF(Tabla1[[#This Row],[EDAD]]<=35,"Adultos jóvenes 18 - 35 años",IF(C8>=36,"Adultos mayores 36 años en adelante")) -> Adultos jóvenes 18 - 35 años | E8: Zapatos | F8: Verde | G8: Nike | H8: MER-A0-4126 | I8: 45320 | J8: =YEAR(Tabla1[[#This Row],[FECHA DE COMPRA]]) -> 2024 | K8: 110 | L8: 0.1 | M8: =Tienda!$K17-Tienda!$K17*Tienda!$L17 -> 133.384 | N8: Efectivo | O8: No | P8: 45320 | Q8: 0
A9: DEP-A0-0084 | B9: Femenino | C9: 24 | D9: =IF(Tabla1[[#This Row],[EDAD]]<=35,"Adultos jóvenes 18 - 35 años",IF(C9>=36,"Adultos mayores 36 años en adelante")) -> Adultos jóvenes 18 - 35 años | E9: Vestido | F9: Verde | G9: Nike | H9: MER-A0-0084 | I9: 45320 | J9: =YEAR(Tabla1[[#This Row],[FECHA DE COMPRA]]) -> 2024 | K9: 125.71 | L9: 0.1 | M9: =Tienda!$K18-Tienda!$K18*Tienda!$L18 -> 28.96 | N9: Efectivo | O9: No | P9: 45320 | Q9: 0
A10: DEP-A0-1801 | B10: Femenino | C10: 20 | D10: =IF(Tabla1[[#This Row],[EDAD]]<=35,"Adultos jóvenes 18 - 35 años",IF(C10>=36,"Adultos mayores 36 años en adelante")) -> Adultos jóvenes 18 - 35 años | E10: Zapatos | F10: Amarillo | G10: Puma | H10: MER-A0-1801 | I10: 45320 | J10: =YEAR(Tabla1[[#This Row],[FECHA DE COMPRA]]) -> 2024 | K10: 144.35 | L10: 0.2 | M10: =Tienda!$K19-Tienda!$K19*Tienda!$L19 -> 24.232 | N10: Efectivo | O10: No | P10: 45320 | Q10: 0
A11: DEP-A0-3447 | B11: Femenino | C11: 32 | D11: =IF(Tabla1[[#This Row],[EDAD]]<=35,"Adultos jóvenes 18 - 35 años",IF(C11>=36,"Adultos mayores 36 años en adelante")) -> Adultos jóvenes 18 - 35 años | E11: Camisa | F11: Rojo | G11: Tommy | H11: MER-A0-3447 | I11: 45322 | J11: =YEAR(Tabla1[[#This Row],[FECHA DE COMPRA]]) -> 2024 | K11: 86.15 | L11: 0.1 | M11: =Tienda!$K20-Tienda!$K20*Tienda!$L20 -> 84.52 | N11: Efectivo | O11: No | P11: 45322 | Q11: 0
A12: DEP-A0-4440 | B12: Femenino | C12: 18 | D12: =IF(Tabla1[[#This Row],[EDAD]]<=35,"Adultos jóvenes 18 - 35 años",IF(C12>=36,"Adultos mayores 36 años en adelante")) -> Adultos jóvenes 18 - 35 años | E12: Chaqueta | F12: Negro | G12: Tommy | H12: MER-A0-4440 | I12: 45325 | J12: =YEAR(Tabla1[[#This Row],[FECHA DE COMPRA]]) -> 2024 | K12: 19.75 | L12: 0 | M12: =Tienda!$K22-Tienda!$K22*Tienda!$L22 -> 87.147 | N12: Efectivo | O12: No | P12: 45325 | Q12: 0
A13: DEP-A0-0153 | B13: Femenino | C13: 34 | D13: =IF(Tabla1[[#This Row],[EDAD]]<=35,"Adultos jóvenes 18 - 35 años",IF(C13>=36,"Adultos mayores 36 años en adelante")) -> Adultos jóvenes 18 - 35 años | E13: Falda | F13: Rojo | G13: Nike | H13: MER-A0-0153 | I13: 45325 | J13: =YEAR(Tabla1[[#This Row],[FECHA DE COMPRA]]) -> 2024 | K13: 62.52 | L13: 0.2 | M13: =Tienda!$K24-Tienda!$K24*Tienda!$L24 -> 37.87 | N13: Efectivo | O13: No | P13: 45325 | Q13: 0
A14: DEP-A0-4820 | B14: Masculino | C14: 18 | D14: =IF(Tabla1[[#This Row],[EDAD]]<=35,"Adultos jóvenes 18 - 35 años",IF(C14>=36,"Adultos mayores 36 años en adelante")) -> Adultos jóvenes 18 - 35 años | E14: Chaqueta | F14: Gris | G14: Zara | H14: MER-A0-4820 | I14: 45325 | J14: =YEAR(Tabla1[[#This Row],[FECHA DE COMPRA]]) -> 2024 | K14: 167.79 | L14: 0.2 | M14: =Tienda!$K25-Tienda!$K25*Tienda!$L25 -> 144.47 | N14: Efectivo | O14: No | P14: 45325 | Q14: 0
A15: DEP-A0-1547 | B15: Masculino | C15: 21 | D15: =IF(Tabla1[[#This Row],[EDAD]]<=35,"Adultos jóvenes 18 - 35 años",IF(C15>=36,"Adultos mayores 36 años en adelante")) -> Adultos jóvenes 18 - 35 años | E15: Zapatos | F15: Gris | G15: Levis | H15: MER-A0-1547 | I15: 45330 | J15: =YEAR(Tabla1[[#This Row],[FECHA DE COMPRA]]) -> 2024 | K15: 97.71 | L15: 0.1 | M15: =Tienda!$K30-Tienda!$K30*Tienda!$L30 -> 32.585 | N15: Efectivo | O15: No | P15: 45330 | Q15: 0
A16: DEP-A0-2742 | B16: Femenino | C16: 35 | D16: =IF(Tabla1[[#This Row],[EDAD]]<=35,"Adultos jóvenes 18 - 35 años",IF(C16>=36,"Adultos mayores 36 años en adelante")) -> Adultos jóvenes 18 - 35 años | E16: Pantalón | F16: Gris | G16: Nike | H16: MER-A0-2742 | I16: 45330 | J16: =YEAR(Tabla1[[#This Row],[FECHA DE COMPRA]]) -> 2024 | K16: 182.89 | L16: 0.3 | M16: =Tienda!$K32-Tienda!$K32*Tienda!$L32 -> 15.984 | N16: Efectivo | O16: No | P16: 45330 | Q16: 0
A17: DEP-A0-2624 | B17: Femenino | C17: 25 | D17: =IF(Tabla1[[#This Row],[EDAD]]<=35,"Adultos jóvenes 18 - 35 años",IF(C17>=36,"Adultos mayores 36 años en adelante")) -> Adultos jóvenes 18 - 35 años | E17: Falda | F17: Gris | G17: Zara | H17: MER-A0-2624 | I17: 45336 | J17: =YEAR(Tabla1[[#This Row],[FECHA DE COMPRA]]) -> 2024 | K17: 166.73 | L17: 0.2 | M17: =Tienda!$K38-Tienda!$K38*Tienda!$L38 -> 146.82 | N17: Efectivo | O17: No | P17: 45336 | Q17: 0
A18: DEP-A0-0966 | B18: Femenino | C18: 24 | D18: =IF(Tabla1[[#This Row],[EDAD]]<=35,"Adultos jóvenes 18 - 35 años",IF(C18>=36,"Adultos mayores 36 años en adelante")) -> Adultos jóvenes 18 - 35 años | E18: Vestido | F18: Rojo | G18: Zara | H18: MER-A0-0966 | I18: 45337 | J18: =YEAR(Tabla1[[#This Row],[FECHA DE COMPRA]]) -> 2024 | K18: 36.2 | L18: 0.2 | M18: =Tienda!$K40-Tienda!$K40*Tienda!$L40 -> 173.448 | N18: Efectivo | O18: No | P18: 45337 | Q18: 0
A19: DEP-A0-2461 | B19: Femenino | C19: 18 | D19: =IF(Tabla1[[#This Row],[EDAD]]<=35,"Adultos jóvenes 18 - 35 años",IF(C19>=36,"Adultos mayores 36 años en adelante")) -> Adultos jóvenes 18 - 35 años | E19: Zapatos | F19: Azul | G19: Adidas | H19: MER-A0-2461 | I19: 45342 | J19: =YEAR(Tabla1[[#This Row],[FECHA DE COMPRA]]) -> 2024 | K19: 30.29 | L19: 0.2 | M19: =Tienda!$K46-Tienda!$K46*Tienda!$L46 -> 60.011 | N19: Efectivo | O19: No | P19: 45342 | Q19: 0
A20: DEP-A0-3469 | B20: Femenino | C20: 20 | D20: =IF(Tabla1[[#This Row],[EDAD]]<=35,"Adultos jóvenes 18 - 35 años",IF(C20>=36,"Adultos mayores 36 años en adelante")) -> Adultos jóvenes 18 - 35 años | E20: Falda | F20: Verde | G20: Puma | H20: MER-A0-3469 | I20: 45342 | J20: =YEAR(Tabla1[[#This Row],[FECHA DE COMPRA]]) -> 2024 | K20: 105.65 | L20: 0.2 | M20: =Tienda!$K48-Tienda!$K48*Tienda!$L48 -> 157.73 | N20: Efectivo | O20: No | P20: 45342 | Q20: 0
A21: DEP-A0-3493 | B21: Femenino | C21: 26 | D21: =IF(Tabla1[[#This Row],[EDAD]]<=35,"Adultos jóvenes 18 - 35 años",IF(C21>=36,"Adultos mayores 36 años en adelante")) -> Adultos jóvenes 18 - 35 años | E21: Blusa | F21: Negro | G21: Tommy | H21: MER-A0-3493 | I21: 45344 | J21: =YEAR(Tabla1[[#This Row],[FECHA DE COMPRA]]) -> 2024 | K21: 74.15 | L21: 0 | M21: =Tienda!$K52-Tienda!$K52*Tienda!$L52 -> 45.68 | N21: Efectivo | O21: No | P21: 45344 | Q21: 0
A22: DEP-A0-0929 | B22: Femenino | C22: 22 | D22: =IF(Tabla1[[#This Row],[EDAD]]<=35,"Adultos jóvenes 18 - 35 años",IF(C22>=36,"Adultos mayores 36 años en adelante")) -> Adultos jóvenes 18 - 35 años | E22: Pantalón | F22: Azul | G22: Nike | H22: MER-A0-0929 | I22: 45344 | J22: =YEAR(Tabla1[[#This Row],[FECHA DE COMPRA]]) -> 2024 | K22: 96.83 | L22: 0.1 | M22: =Tienda!$K53-Tienda!$K53*Tienda!$L53 -> 105.4 | N22: Efectivo | O22: No | P22: 45344 | Q22: 0
A23: DEP-A0-3515 | B23: Femenino | C23: 24 | D23: =IF(Tabla1[[#This Row],[EDAD]]<=35,"Adultos jóvenes 18 - 35 años",IF(C23>=36,"Adultos mayores 36 años en adelante")) -> Adultos jóvenes 18 - 35 años | E23: Zapatos | F23: Azul | G23: Levis | H23: MER-A0-3515 | I23: 45344 | J23: =YEAR(Tabla1[[#This Row],[FECHA DE COMPRA]]) -> 2024 | K23: 190.13 | L23: 0.1 | M23: =Tienda!$K55-Tienda!$K55*Tienda!$L55 -> 89.019 | N23: Efectivo | O23: No | P23: 45344 | Q23: 0
A24: DEP-A0-3698 | B24: Femenino | C24: 24 | D24: =IF(Tabla1[[#This Row],[EDAD]]<=35,"Adultos jóvenes 18 - 35 años",IF(C24>=36,"Adultos mayores 36 años en adelante")) -> Adultos jóvenes 18 - 35 años | E24: Blusa | F24: Gris | G24: Zara | H24: MER-A0-3698 | I24: 45349 | J24: =YEAR(Tabla1[[#This Row],[FECHA DE COMPRA]]) -> 2024 | K24: 37.87 | L24: 0 | M24: =Tienda!$K61-Tienda!$K61*Tienda!$L61 -> 34.51 | N24: Efectivo | O24: No | P24: 45349 | Q24: 0
A25: DEP-A0-2456 | B25: Femenino | C25: 33 | D25: =IF(Tabla1[[#This Row],[EDAD]]<=35,"Adultos jóvenes 18 - 35 años",IF(C25>=36,"Adultos mayores 36 años en adelante")) -> Adultos jóvenes 18 - 35 años | E25: Blusa | F25: Azul | G25: Mango | H25: MER-A0-2456 | I25: 45335 | J25: =YEAR(Tabla1[[#This Row],[FECHA DE COMPRA]]) -> 2024 | K25: 144.47 | L25: 0 | M25: =Tienda!$K64-Tienda!$K64*Tienda!$L64 -> 138.456 | N25: Efectivo | O25: No | P25: 45371 | Q25: 0
A26: DEP-A0-3450 | B26: Femenino | C26: 34 | D26: =IF(Tabla1[[#This Row],[EDAD]]<=35,"Adultos jóvenes 18 - 35 años",IF(C26>=36,"Adultos mayores 36 años en adelante")) -> Adultos jóvenes 18 - 35 años | E26: Pantalón | F26: Azul | G26: Nike | H26: MER-A0-3450 | I26: 45335 | J26: =YEAR(Tabla1[[#This Row],[FECHA DE COMPRA]]) -> 2024 | K26: 106.54 | L26: 0.1 | M26: =Tienda!$K65-Tienda!$K65*Tienda!$L65 -> 7.056 | N26: Efectivo | O26: No | P26: 45373 | Q26: 0
A27: DEP-A0-0441 | B27: Femenino | C27: 22 | D27: =IF(Tabla1[[#This Row],[EDAD]]<=35,"Adultos jóvenes 18 - 35 años",IF(C27>=36,"Adultos mayores 36 años en adelante")) -> Adultos jóvenes 18 - 35 años | E27: Camisa | F27: Blanco | G27: Puma | H27: MER-A0-0441 | I27: 45335 | J27: =YEAR(Tabla1[[#This Row],[FECHA DE COMPRA]]) -> 2024 | K27: 128.9 | L27: 0.3 | M27: =Tienda!$K66-Tienda!$K66*Tienda!$L66 -> 56.105 | N27: Efectivo | O27: No | P27: 45373 | Q27: 0
A28: DEP-A0-0079 | B28: Femenino | C28: 21 | D28: =IF(Tabla1[[#This Row],[EDAD]]<=35,"Adultos jóvenes 18 - 35 años",IF(C28>=36,"Adultos mayores 36 años en adelante")) -> Adultos jóvenes 18 - 35 años | E28: Blusa | F28: Gris | G28: Levis | H28: MER-A0-0079 | I28: 45335 | J28: =YEAR(Tabla1[[#This Row],[FECHA DE COMPRA]]) -> 2024 | K28: 177.21 | L28: 0 | M28: =Tienda!$K67-Tienda!$K67*Tienda!$L67 -> 165.46 | N28: Efectivo | O28: No | P28: 45375 | Q28: 0
A29: DEP-A0-1068 | B29: Masculino | C29: 30 | D29: =IF(Tabla1[[#This Row],[EDAD]]<=35,"Adultos jóvenes 18 - 35 años",IF(C29>=36,"Adultos mayores 36 años en adelante")) -> Adultos jóvenes 18 - 35 años | E29: Chaqueta | F29: Verde | G29: Mango | H29: MER-A0-1068 | I29: 45352 | J29: =YEAR(Tabla1[[#This Row],[FECHA DE COMPRA]]) -> 2024 | K29: 91.63 | L29: 0.1 | M29: =Tienda!$K70-Tienda!$K70*Tienda!$L70 -> 86.4 | N29: Efectivo | O29: No | P29: 45352 | Q29: 0
A30: DEP-A0-0112 | B30: Masculino | C30: 22 | D30: =IF(Tabla1[[#This Row],[EDAD]]<=35,"Adultos jóvenes 18 - 35 años",IF(C30>=36,"Adultos mayores 36 años en adelante")) -> Adultos jóvenes 18 - 35 años | E30: Zapatos | F30: Verde | G30: Levis | H30: MER-A0-0112 | I30: 45354 | J30: =YEAR(Tabla1[[#This Row],[FECHA DE COMPRA]]) -> 2024 | K30: 46.55 | L30: 0.3 | M30: =Tienda!$K72-Tienda!$K72*Tienda!$L72 -> 82.296 | N30: Efectivo | O30: No | P30: 45354 | Q30: 0
A31: DEP-A0-2097 | B31: Femenino | C31: 29 | D31: =IF(Tabla1[[#This Row],[EDAD]]<=35,"Adultos jóvenes 18 - 35 años",IF(C31>=36,"Adultos mayores 36 años en adelante")) -> Adultos jóvenes 18 - 35 años | E31: Vestido | F31: Rojo | G31: Mango | H31: MER-A0-2097 | I31: 45354 | J31: =YEAR(Tabla1[[#This Row],[FECHA DE COMPRA]]) -> 2024 | K31: 66.63 | L31: 0.2 | M31: =Tienda!$K73-Tienda!$K73*Tienda!$L73 -> 88.634 | N31: Efectivo | O31: No | P31: 45354 | Q31: 0
A32: DEP-A0-1776 | B32: Femenino | C32: 26 | D32: =IF(Tabla1[[#This Row],[EDAD]]<=35,"Adultos jóvenes 18 - 35 años",IF(C32>=36,"Adultos mayores 36 años en adelante")) -> Adultos jóvenes 18 - 35 años | E32: Chaqueta | F32: Negro | G32: Tommy | H32: MER-A0-1776 | I32: 45356 | J32: =YEAR(Tabla1[[#This Row],[FECHA DE COMPRA]]) -> 2024 | K32: 19.98 | L32: 0.2 | M32: =Tienda!$K76-Tienda!$K76*Tienda!$L76 -> 31.297 | N32: Efectivo | O32: No | P32: 45356 | Q32: 0
A33: DEP-A0-3152 | B33: Masculino | C33: 29 | D33: =IF(Tabla1[[#This Row],[EDAD]]<=35,"Adultos jóvenes 18 - 35 años",IF(C33>=36,"Adultos mayores 36 años en adelante")) -> Adultos jóvenes 18 - 35 años | E33: Chaqueta | F33: Rojo | G33: Tommy | H33: MER-A0-3152 | I33: 45356 | J33: =YEAR(Tabla1[[#This Row],[FECHA DE COMPRA]]) -> 2024 | K33: 140.78 | L33: 0.3 | M33: =Tienda!$K78-Tienda!$K78*Tienda!$L78 -> 47.7 | N33: Efectivo | O33: No | P33: 45356 | Q33: 0
A34: DEP-A0-4394 | B34: Femenino | C34: 25 | D34: =IF(Tabla1[[#This Row],[EDAD]]<=35,"Adultos jóvenes 18 - 35 años",IF(C34>=36,"Adultos mayores 36 años en adelante")) -> Adultos jóvenes 18 - 35 años | E34: Blusa | F34: Blanco | G34: Zara | H34: MER-A0-4394 | I34: 45361 | J34: =YEAR(Tabla1[[#This Row],[FECHA DE COMPRA]]) -> 2024 | K34: 111.82 | L34: 0.2 | M34: =Tienda!$K84-Tienda!$K84*Tienda!$L84 -> 180.76 | N34: Efectivo | O34: No | P34: 45361 | Q34: 0
A35: DEP-A0-1317 | B35: Femenino | C35: 18 | D35: =IF(Tabla1[[#This Row],[EDAD]]<=35,"Adultos jóvenes 18 - 35 años",IF(C35>=36,"Adultos mayores 36 años en adelante")) -> Adultos jóvenes 18 - 35 años | E35: Vestido | F35: Negro | G35: Zara | H35: MER-A0-1317 | I35: 45361 | J35: =YEAR(Tabla1[[#This Row],[FECHA DE COMPRA]]) -> 2024 | K35: 153.58 | L35: 0.2 | M35: =Tienda!$K85-Tienda!$K85*Tienda!$L85 -> 94.635 | N35: Efectivo | O35: No | P35: 45361 | Q35: 0
A36: DEP-A0-0785 | B36: Femenino | C36: 29 | D36: =IF(Tabla1[[#This Row],[EDAD]]<=35,"Adultos jóvenes 18 - 35 años",IF(C36>=36,"Adultos mayores 36 años en adelante")) -> Adultos jóvenes 18 - 35 años | E36: Blusa | F36: Verde | G36: Zara | H36: MER-A0-0785 | I36: 45362 | J36: =YEAR(Tabla1[[#This Row],[FECHA DE COMPRA]]) -> 2024 | K36: 38.58 | L36: 0.1 | M36: =Tienda!$K86-Tienda!$K86*Tienda!$L86 -> 135.24 | N36: Efectivo | O36: No | P36: 45362 | Q36: 0
A37: DEP-A0-3475 | B37: Femenino | C37: 21 | D37: =IF(Tabla1[[#This Row],[EDAD]]<=35,"Adultos jóvenes 18 - 35 años",IF(C37>=36,"Adultos mayores 36 años en adelante")) -> Adultos jóvenes 18 - 35 años | E37: Zapatos | F37: Negro | G37: Zara | H37: MER-A0-3475 | I37: 45364 | J37: =YEAR(Tabla1[[#This Row],[FECHA DE COMPRA]]) -> 2024 | K37: 134.2 | L37: 0.3 | M37: =Tienda!$K87-Tienda!$K87*Tienda!$L87 -> 66.28 | N37: Efectivo | O37: No | P37: 45364 | Q37: 0
A38: DEP-A0-4443 | B38: Masculino | C38: 20 | D38: =IF(Tabla1[[#This Row],[EDAD]]<=35,"Adultos jóvenes 18 - 35 años",IF(C38>=36,"Adultos mayores 36 años en adelante")) -> Adultos jóvenes 18 - 35 años | E38: Chaqueta | F38: Rojo | G38: Zara | H38: MER-A0-4443 | I38: 45365 | J38: =YEAR(Tabla1[[#This Row],[FECHA DE COMPRA]]) -> 2024 | K38: 146.82 | L38: 0 | M38: =Tienda!$K93-Tienda!$K93*Tienda!$L93 -> 78.96 | N38: Efectivo | O38: No | P38: 45365 | Q38: 0
A39: DEP-A0-0232 | B39: Masculino | C39: 19 | D39: =IF(Tabla1[[#This Row],[EDAD]]<=35,"Adultos jóvenes 18 - 35 años",IF(C39>=36,"Adultos mayores 36 años en adelante")) -> Adultos jóvenes 18 - 35 años | E39: Chaqueta | F39: Amarillo | G39: Zara | H39: MER-A0-0232 | I39: 45365 | J39: =YEAR(Tabla1[[#This Row],[FECHA DE COMPRA]]) -> 2024 | K39: 198.04 | L39: 0.1 | M39: =Tienda!$K94-Tienda!$K94*Tienda!$L94 -> 119.511 | N39: Efectivo | O39: No | P39: 45365 | Q39: 0
A40: DEP-A0-3173 | B40: Femenino | C40: 35 | D40: =IF(Tabla1[[#This Row],[EDAD]]<=35,"Adultos jóvenes 18 - 35 años",IF(C40>=36,"Adultos mayores 36 años en adelante")) -> Adultos jóvenes 18 - 35 años | E40: Blusa | F40: Negro | G40: Levis | H40: MER-A0-3173 | I40: 45375 | J40: =YEAR(Tabla1[[#This Row],[FECHA DE COMPRA]]) -> 2024 | K40: 192.72 | L40: 0.1 | M40: =Tienda!$K96-Tienda!$K96*Tienda!$L96 -> 84.942 | N40: Efectivo | O40: No | P40: 45375 | Q40: 0
...

Sheet Resumen Género
A1: Recomendación: Usar la función =CONTAR.SI.CONJUNTO()
A2: Género | B2: 2024 | C2: 2025
A3: Masculino | B3: =COUNTIFS(Tabla1[AÑO DE COMPRA],'Resumen Género'!B2,Tabla1[GENERO],'Resumen Género'!A3) -> 859 | C3: =COUNTIFS(Tabla1[AÑO DE COMPRA],'Resumen Género'!C2,Tabla1[GENERO],'Resumen Género'!A3) -> 511
A4: Femenino | B4: =COUNTIFS(Tabla1[AÑO DE COMPRA],'Resumen Género'!B2,Tabla1[GENERO],'Resumen Género'!A4) -> 2243 | C4: =COUNTIFS(Tabla1[AÑO DE COMPRA],'Resumen Género'!C2,Tabla1[GENERO],'Resumen Género'!A4) -> 1387
A5: Recomendación: Usar la función =PROMEDIO.SI()
A6: Tipo de pago | B6: Total a pagar
A7: Efectivo | B7: =AVERAGEIF(Tienda!N2:N5001,'Resumen Género'!A7,Tienda!M2:M5001) -> 94.120794
A8: Tarjeta de crédito | B8: =AVERAGEIF(Tienda!N2:N5001,'Resumen Género'!A8,Tienda!M2:M5001) -> 82.938656
A9: Tarjeta Deprati | B9: =AVERAGEIF(Tienda!N2:N5001,'Resumen Género'!A9,Tienda!M2:M5001) -> 94.799386
A10: Recomendación: Usar la función =CONTAR.SI()
A11: Clientes | B11: Edades
A12: Adultos jóvenes 18 - 35 años | B12: =COUNTIF(Tienda!C2:C5001,"<=35") -> 1856
A13: Adultos mayores 36 años en adelante | B13: =COUNTIF(Tienda!C2:C5001,">35") -> 3144
